[2022-09-27 16:09:28,910] {taskinstance.py:1032} INFO - Dependencies all met for <TaskInstance: local_data_ingestion_gcs_dag.local_to_gcs_task scheduled__2022-09-26T00:00:00+00:00 [queued]>
[2022-09-27 16:09:29,059] {taskinstance.py:1032} INFO - Dependencies all met for <TaskInstance: local_data_ingestion_gcs_dag.local_to_gcs_task scheduled__2022-09-26T00:00:00+00:00 [queued]>
[2022-09-27 16:09:29,070] {taskinstance.py:1238} INFO - 
--------------------------------------------------------------------------------
[2022-09-27 16:09:29,072] {taskinstance.py:1239} INFO - Starting attempt 2 of 2
[2022-09-27 16:09:29,073] {taskinstance.py:1240} INFO - 
--------------------------------------------------------------------------------
[2022-09-27 16:09:29,204] {taskinstance.py:1259} INFO - Executing <Task(PythonOperator): local_to_gcs_task> on 2022-09-26 00:00:00+00:00
[2022-09-27 16:09:29,214] {standard_task_runner.py:52} INFO - Started process 76 to run task
[2022-09-27 16:09:29,230] {standard_task_runner.py:76} INFO - Running: ['***', 'tasks', 'run', 'local_data_ingestion_gcs_dag', 'local_to_gcs_task', 'scheduled__2022-09-26T00:00:00+00:00', '--job-id', '107', '--raw', '--subdir', 'DAGS_FOLDER/data_upload_to_gcs.py', '--cfg-path', '/tmp/tmpfdmdfyud', '--error-file', '/tmp/tmpzg6wsfgv']
[2022-09-27 16:09:29,249] {standard_task_runner.py:77} INFO - Job 107: Subtask local_to_gcs_task
[2022-09-27 16:09:29,447] {logging_mixin.py:109} INFO - Running <TaskInstance: local_data_ingestion_gcs_dag.local_to_gcs_task scheduled__2022-09-26T00:00:00+00:00 [running]> on host 87273c472e58
[2022-09-27 16:09:29,790] {taskinstance.py:1426} INFO - Exporting the following env vars:
AIRFLOW_CTX_DAG_OWNER=***
AIRFLOW_CTX_DAG_ID=local_data_ingestion_gcs_dag
AIRFLOW_CTX_TASK_ID=local_to_gcs_task
AIRFLOW_CTX_EXECUTION_DATE=2022-09-26T00:00:00+00:00
AIRFLOW_CTX_DAG_RUN_ID=scheduled__2022-09-26T00:00:00+00:00
[2022-09-27 16:09:29,929] {taskinstance.py:1700} ERROR - Task failed with exception
Traceback (most recent call last):
  File "/home/airflow/.local/lib/python3.7/site-packages/airflow/models/taskinstance.py", line 1329, in _run_raw_task
    self._execute_task_with_callbacks(context)
  File "/home/airflow/.local/lib/python3.7/site-packages/airflow/models/taskinstance.py", line 1455, in _execute_task_with_callbacks
    result = self._execute_task(context, self.task)
  File "/home/airflow/.local/lib/python3.7/site-packages/airflow/models/taskinstance.py", line 1511, in _execute_task
    result = execute_callable(context=context)
  File "/home/airflow/.local/lib/python3.7/site-packages/airflow/operators/python.py", line 174, in execute
    return_value = self.execute_callable()
  File "/home/airflow/.local/lib/python3.7/site-packages/airflow/operators/python.py", line 185, in execute_callable
    return self.python_callable(*self.op_args, **self.op_kwargs)
  File "/opt/airflow/dags/data_upload_to_gcs.py", line 34, in upload_to_gcs
    blob.upload_from_filename(local_file)
  File "/home/airflow/.local/lib/python3.7/site-packages/google/cloud/storage/blob.py", line 2720, in upload_from_filename
    with open(filename, "rb") as file_obj:
FileNotFoundError: [Errno 2] No such file or directory: 'C:/Users/Febian/Documents/Google_cloud/Proyek/File/countries.csv'
[2022-09-27 16:09:30,058] {taskinstance.py:1277} INFO - Marking task as FAILED. dag_id=local_data_ingestion_gcs_dag, task_id=local_to_gcs_task, execution_date=20220926T000000, start_date=20220927T160928, end_date=20220927T160930
[2022-09-27 16:09:30,135] {standard_task_runner.py:92} ERROR - Failed to execute job 107 for task local_to_gcs_task
Traceback (most recent call last):
  File "/home/airflow/.local/lib/python3.7/site-packages/airflow/task/task_runner/standard_task_runner.py", line 85, in _start_by_fork
    args.func(args, dag=self.dag)
  File "/home/airflow/.local/lib/python3.7/site-packages/airflow/cli/cli_parser.py", line 48, in command
    return func(*args, **kwargs)
  File "/home/airflow/.local/lib/python3.7/site-packages/airflow/utils/cli.py", line 92, in wrapper
    return f(*args, **kwargs)
  File "/home/airflow/.local/lib/python3.7/site-packages/airflow/cli/commands/task_command.py", line 298, in task_run
    _run_task_by_selected_method(args, dag, ti)
  File "/home/airflow/.local/lib/python3.7/site-packages/airflow/cli/commands/task_command.py", line 107, in _run_task_by_selected_method
    _run_raw_task(args, ti)
  File "/home/airflow/.local/lib/python3.7/site-packages/airflow/cli/commands/task_command.py", line 184, in _run_raw_task
    error_file=args.error_file,
  File "/home/airflow/.local/lib/python3.7/site-packages/airflow/utils/session.py", line 70, in wrapper
    return func(*args, session=session, **kwargs)
  File "/home/airflow/.local/lib/python3.7/site-packages/airflow/models/taskinstance.py", line 1329, in _run_raw_task
    self._execute_task_with_callbacks(context)
  File "/home/airflow/.local/lib/python3.7/site-packages/airflow/models/taskinstance.py", line 1455, in _execute_task_with_callbacks
    result = self._execute_task(context, self.task)
  File "/home/airflow/.local/lib/python3.7/site-packages/airflow/models/taskinstance.py", line 1511, in _execute_task
    result = execute_callable(context=context)
  File "/home/airflow/.local/lib/python3.7/site-packages/airflow/operators/python.py", line 174, in execute
    return_value = self.execute_callable()
  File "/home/airflow/.local/lib/python3.7/site-packages/airflow/operators/python.py", line 185, in execute_callable
    return self.python_callable(*self.op_args, **self.op_kwargs)
  File "/opt/airflow/dags/data_upload_to_gcs.py", line 34, in upload_to_gcs
    blob.upload_from_filename(local_file)
  File "/home/airflow/.local/lib/python3.7/site-packages/google/cloud/storage/blob.py", line 2720, in upload_from_filename
    with open(filename, "rb") as file_obj:
FileNotFoundError: [Errno 2] No such file or directory: 'C:/Users/Febian/Documents/Google_cloud/Proyek/File/countries.csv'
[2022-09-27 16:09:30,169] {local_task_job.py:154} INFO - Task exited with return code 1
[2022-09-27 16:09:30,559] {local_task_job.py:264} INFO - 0 downstream tasks scheduled from follow-on schedule check
[2022-09-27 16:55:53,648] {taskinstance.py:1032} INFO - Dependencies all met for <TaskInstance: local_data_ingestion_gcs_dag.local_to_gcs_task scheduled__2022-09-26T00:00:00+00:00 [queued]>
[2022-09-27 16:55:53,668] {taskinstance.py:1032} INFO - Dependencies all met for <TaskInstance: local_data_ingestion_gcs_dag.local_to_gcs_task scheduled__2022-09-26T00:00:00+00:00 [queued]>
[2022-09-27 16:55:53,669] {taskinstance.py:1238} INFO - 
--------------------------------------------------------------------------------
[2022-09-27 16:55:53,669] {taskinstance.py:1239} INFO - Starting attempt 2 of 2
[2022-09-27 16:55:53,670] {taskinstance.py:1240} INFO - 
--------------------------------------------------------------------------------
[2022-09-27 16:55:53,708] {taskinstance.py:1259} INFO - Executing <Task(PythonOperator): local_to_gcs_task> on 2022-09-26 00:00:00+00:00
[2022-09-27 16:55:53,715] {standard_task_runner.py:52} INFO - Started process 255 to run task
[2022-09-27 16:55:53,720] {standard_task_runner.py:76} INFO - Running: ['***', 'tasks', 'run', 'local_data_ingestion_gcs_dag', 'local_to_gcs_task', 'scheduled__2022-09-26T00:00:00+00:00', '--job-id', '127', '--raw', '--subdir', 'DAGS_FOLDER/data_upload_to_gcs.py', '--cfg-path', '/tmp/tmpbdqsrs_5', '--error-file', '/tmp/tmpu_8zxgqu']
[2022-09-27 16:55:53,722] {standard_task_runner.py:77} INFO - Job 127: Subtask local_to_gcs_task
[2022-09-27 16:55:53,802] {logging_mixin.py:109} INFO - Running <TaskInstance: local_data_ingestion_gcs_dag.local_to_gcs_task scheduled__2022-09-26T00:00:00+00:00 [running]> on host af9dd8838ec0
[2022-09-27 16:55:53,908] {taskinstance.py:1426} INFO - Exporting the following env vars:
AIRFLOW_CTX_DAG_OWNER=***
AIRFLOW_CTX_DAG_ID=local_data_ingestion_gcs_dag
AIRFLOW_CTX_TASK_ID=local_to_gcs_task
AIRFLOW_CTX_EXECUTION_DATE=2022-09-26T00:00:00+00:00
AIRFLOW_CTX_DAG_RUN_ID=scheduled__2022-09-26T00:00:00+00:00
[2022-09-27 16:55:53,942] {taskinstance.py:1700} ERROR - Task failed with exception
Traceback (most recent call last):
  File "/home/airflow/.local/lib/python3.7/site-packages/airflow/models/taskinstance.py", line 1329, in _run_raw_task
    self._execute_task_with_callbacks(context)
  File "/home/airflow/.local/lib/python3.7/site-packages/airflow/models/taskinstance.py", line 1455, in _execute_task_with_callbacks
    result = self._execute_task(context, self.task)
  File "/home/airflow/.local/lib/python3.7/site-packages/airflow/models/taskinstance.py", line 1511, in _execute_task
    result = execute_callable(context=context)
  File "/home/airflow/.local/lib/python3.7/site-packages/airflow/operators/python.py", line 174, in execute
    return_value = self.execute_callable()
  File "/home/airflow/.local/lib/python3.7/site-packages/airflow/operators/python.py", line 185, in execute_callable
    return self.python_callable(*self.op_args, **self.op_kwargs)
  File "/opt/airflow/dags/data_upload_to_gcs.py", line 36, in upload_to_gcs
    blob.upload_from_filename(local_file)
  File "/home/airflow/.local/lib/python3.7/site-packages/google/cloud/storage/blob.py", line 2720, in upload_from_filename
    with open(filename, "rb") as file_obj:
FileNotFoundError: [Errno 2] No such file or directory: 'C:/Users/Febian/Documents/Google_cloud/Proyek/File/countries.csv'
[2022-09-27 16:55:53,972] {taskinstance.py:1277} INFO - Marking task as FAILED. dag_id=local_data_ingestion_gcs_dag, task_id=local_to_gcs_task, execution_date=20220926T000000, start_date=20220927T165553, end_date=20220927T165553
[2022-09-27 16:55:53,997] {standard_task_runner.py:92} ERROR - Failed to execute job 127 for task local_to_gcs_task
Traceback (most recent call last):
  File "/home/airflow/.local/lib/python3.7/site-packages/airflow/task/task_runner/standard_task_runner.py", line 85, in _start_by_fork
    args.func(args, dag=self.dag)
  File "/home/airflow/.local/lib/python3.7/site-packages/airflow/cli/cli_parser.py", line 48, in command
    return func(*args, **kwargs)
  File "/home/airflow/.local/lib/python3.7/site-packages/airflow/utils/cli.py", line 92, in wrapper
    return f(*args, **kwargs)
  File "/home/airflow/.local/lib/python3.7/site-packages/airflow/cli/commands/task_command.py", line 298, in task_run
    _run_task_by_selected_method(args, dag, ti)
  File "/home/airflow/.local/lib/python3.7/site-packages/airflow/cli/commands/task_command.py", line 107, in _run_task_by_selected_method
    _run_raw_task(args, ti)
  File "/home/airflow/.local/lib/python3.7/site-packages/airflow/cli/commands/task_command.py", line 184, in _run_raw_task
    error_file=args.error_file,
  File "/home/airflow/.local/lib/python3.7/site-packages/airflow/utils/session.py", line 70, in wrapper
    return func(*args, session=session, **kwargs)
  File "/home/airflow/.local/lib/python3.7/site-packages/airflow/models/taskinstance.py", line 1329, in _run_raw_task
    self._execute_task_with_callbacks(context)
  File "/home/airflow/.local/lib/python3.7/site-packages/airflow/models/taskinstance.py", line 1455, in _execute_task_with_callbacks
    result = self._execute_task(context, self.task)
  File "/home/airflow/.local/lib/python3.7/site-packages/airflow/models/taskinstance.py", line 1511, in _execute_task
    result = execute_callable(context=context)
  File "/home/airflow/.local/lib/python3.7/site-packages/airflow/operators/python.py", line 174, in execute
    return_value = self.execute_callable()
  File "/home/airflow/.local/lib/python3.7/site-packages/airflow/operators/python.py", line 185, in execute_callable
    return self.python_callable(*self.op_args, **self.op_kwargs)
  File "/opt/airflow/dags/data_upload_to_gcs.py", line 36, in upload_to_gcs
    blob.upload_from_filename(local_file)
  File "/home/airflow/.local/lib/python3.7/site-packages/google/cloud/storage/blob.py", line 2720, in upload_from_filename
    with open(filename, "rb") as file_obj:
FileNotFoundError: [Errno 2] No such file or directory: 'C:/Users/Febian/Documents/Google_cloud/Proyek/File/countries.csv'
[2022-09-27 16:55:54,016] {local_task_job.py:154} INFO - Task exited with return code 1
[2022-09-27 16:55:54,080] {local_task_job.py:264} INFO - 0 downstream tasks scheduled from follow-on schedule check
