[2022-09-27 06:00:32,539] {taskinstance.py:1032} INFO - Dependencies all met for <TaskInstance: first_dag.accurate scheduled__2022-09-26T00:00:00+00:00 [queued]>
[2022-09-27 06:00:32,710] {taskinstance.py:1032} INFO - Dependencies all met for <TaskInstance: first_dag.accurate scheduled__2022-09-26T00:00:00+00:00 [queued]>
[2022-09-27 06:00:32,714] {taskinstance.py:1238} INFO - 
--------------------------------------------------------------------------------
[2022-09-27 06:00:32,716] {taskinstance.py:1239} INFO - Starting attempt 1 of 1
[2022-09-27 06:00:32,722] {taskinstance.py:1240} INFO - 
--------------------------------------------------------------------------------
[2022-09-27 06:00:32,838] {taskinstance.py:1259} INFO - Executing <Task(BashOperator): accurate> on 2022-09-26 00:00:00+00:00
[2022-09-27 06:00:32,871] {standard_task_runner.py:52} INFO - Started process 120 to run task
[2022-09-27 06:00:32,905] {standard_task_runner.py:76} INFO - Running: ['***', 'tasks', 'run', 'first_dag', 'accurate', 'scheduled__2022-09-26T00:00:00+00:00', '--job-id', '77', '--raw', '--subdir', 'DAGS_FOLDER/xcom_dag.py', '--cfg-path', '/tmp/tmpastnb3pp', '--error-file', '/tmp/tmpv23fv63u']
[2022-09-27 06:00:32,937] {standard_task_runner.py:77} INFO - Job 77: Subtask accurate
[2022-09-27 06:00:33,574] {logging_mixin.py:109} INFO - Running <TaskInstance: first_dag.accurate scheduled__2022-09-26T00:00:00+00:00 [running]> on host 2302558ab94b
[2022-09-27 06:00:33,830] {taskinstance.py:1426} INFO - Exporting the following env vars:
AIRFLOW_CTX_DAG_OWNER=***
AIRFLOW_CTX_DAG_ID=first_dag
AIRFLOW_CTX_TASK_ID=accurate
AIRFLOW_CTX_EXECUTION_DATE=2022-09-26T00:00:00+00:00
AIRFLOW_CTX_DAG_RUN_ID=scheduled__2022-09-26T00:00:00+00:00
[2022-09-27 06:00:33,841] {subprocess.py:62} INFO - Tmp dir root location: 
 /tmp
[2022-09-27 06:00:33,847] {subprocess.py:74} INFO - Running command: ['bash', '-c', "echo 'accurate"]
[2022-09-27 06:00:33,879] {subprocess.py:85} INFO - Output:
[2022-09-27 06:00:33,886] {subprocess.py:89} INFO - bash: -c: line 0: unexpected EOF while looking for matching `''
[2022-09-27 06:00:33,887] {subprocess.py:89} INFO - bash: -c: line 1: syntax error: unexpected end of file
[2022-09-27 06:00:33,888] {subprocess.py:93} INFO - Command exited with return code 1
[2022-09-27 06:00:33,963] {taskinstance.py:1700} ERROR - Task failed with exception
Traceback (most recent call last):
  File "/home/airflow/.local/lib/python3.7/site-packages/airflow/models/taskinstance.py", line 1329, in _run_raw_task
    self._execute_task_with_callbacks(context)
  File "/home/airflow/.local/lib/python3.7/site-packages/airflow/models/taskinstance.py", line 1455, in _execute_task_with_callbacks
    result = self._execute_task(context, self.task)
  File "/home/airflow/.local/lib/python3.7/site-packages/airflow/models/taskinstance.py", line 1511, in _execute_task
    result = execute_callable(context=context)
  File "/home/airflow/.local/lib/python3.7/site-packages/airflow/operators/bash.py", line 188, in execute
    f'Bash command failed. The command returned a non-zero exit code {result.exit_code}.'
airflow.exceptions.AirflowException: Bash command failed. The command returned a non-zero exit code 1.
[2022-09-27 06:00:33,999] {taskinstance.py:1277} INFO - Marking task as FAILED. dag_id=first_dag, task_id=accurate, execution_date=20220926T000000, start_date=20220927T060032, end_date=20220927T060033
[2022-09-27 06:00:34,092] {standard_task_runner.py:92} ERROR - Failed to execute job 77 for task accurate
Traceback (most recent call last):
  File "/home/airflow/.local/lib/python3.7/site-packages/airflow/task/task_runner/standard_task_runner.py", line 85, in _start_by_fork
    args.func(args, dag=self.dag)
  File "/home/airflow/.local/lib/python3.7/site-packages/airflow/cli/cli_parser.py", line 48, in command
    return func(*args, **kwargs)
  File "/home/airflow/.local/lib/python3.7/site-packages/airflow/utils/cli.py", line 92, in wrapper
    return f(*args, **kwargs)
  File "/home/airflow/.local/lib/python3.7/site-packages/airflow/cli/commands/task_command.py", line 298, in task_run
    _run_task_by_selected_method(args, dag, ti)
  File "/home/airflow/.local/lib/python3.7/site-packages/airflow/cli/commands/task_command.py", line 107, in _run_task_by_selected_method
    _run_raw_task(args, ti)
  File "/home/airflow/.local/lib/python3.7/site-packages/airflow/cli/commands/task_command.py", line 184, in _run_raw_task
    error_file=args.error_file,
  File "/home/airflow/.local/lib/python3.7/site-packages/airflow/utils/session.py", line 70, in wrapper
    return func(*args, session=session, **kwargs)
  File "/home/airflow/.local/lib/python3.7/site-packages/airflow/models/taskinstance.py", line 1329, in _run_raw_task
    self._execute_task_with_callbacks(context)
  File "/home/airflow/.local/lib/python3.7/site-packages/airflow/models/taskinstance.py", line 1455, in _execute_task_with_callbacks
    result = self._execute_task(context, self.task)
  File "/home/airflow/.local/lib/python3.7/site-packages/airflow/models/taskinstance.py", line 1511, in _execute_task
    result = execute_callable(context=context)
  File "/home/airflow/.local/lib/python3.7/site-packages/airflow/operators/bash.py", line 188, in execute
    f'Bash command failed. The command returned a non-zero exit code {result.exit_code}.'
airflow.exceptions.AirflowException: Bash command failed. The command returned a non-zero exit code 1.
[2022-09-27 06:00:34,179] {local_task_job.py:154} INFO - Task exited with return code 1
[2022-09-27 06:00:34,301] {local_task_job.py:264} INFO - 0 downstream tasks scheduled from follow-on schedule check
[2022-09-27 17:14:18,813] {taskinstance.py:1032} INFO - Dependencies all met for <TaskInstance: first_dag.accurate scheduled__2022-09-26T00:00:00+00:00 [queued]>
[2022-09-27 17:14:18,863] {taskinstance.py:1032} INFO - Dependencies all met for <TaskInstance: first_dag.accurate scheduled__2022-09-26T00:00:00+00:00 [queued]>
[2022-09-27 17:14:18,865] {taskinstance.py:1238} INFO - 
--------------------------------------------------------------------------------
[2022-09-27 17:14:18,866] {taskinstance.py:1239} INFO - Starting attempt 1 of 1
[2022-09-27 17:14:18,866] {taskinstance.py:1240} INFO - 
--------------------------------------------------------------------------------
[2022-09-27 17:14:18,906] {taskinstance.py:1259} INFO - Executing <Task(BashOperator): accurate> on 2022-09-26 00:00:00+00:00
[2022-09-27 17:14:18,912] {standard_task_runner.py:52} INFO - Started process 168 to run task
[2022-09-27 17:14:18,916] {standard_task_runner.py:76} INFO - Running: ['***', 'tasks', 'run', 'first_dag', 'accurate', 'scheduled__2022-09-26T00:00:00+00:00', '--job-id', '145', '--raw', '--subdir', 'DAGS_FOLDER/xcom_dag.py', '--cfg-path', '/tmp/tmpujlkewbt', '--error-file', '/tmp/tmphq1sh060']
[2022-09-27 17:14:18,917] {standard_task_runner.py:77} INFO - Job 145: Subtask accurate
[2022-09-27 17:14:19,086] {logging_mixin.py:109} INFO - Running <TaskInstance: first_dag.accurate scheduled__2022-09-26T00:00:00+00:00 [running]> on host f5057273dea0
[2022-09-27 17:14:19,277] {taskinstance.py:1426} INFO - Exporting the following env vars:
AIRFLOW_CTX_DAG_OWNER=***
AIRFLOW_CTX_DAG_ID=first_dag
AIRFLOW_CTX_TASK_ID=accurate
AIRFLOW_CTX_EXECUTION_DATE=2022-09-26T00:00:00+00:00
AIRFLOW_CTX_DAG_RUN_ID=scheduled__2022-09-26T00:00:00+00:00
[2022-09-27 17:14:19,280] {subprocess.py:62} INFO - Tmp dir root location: 
 /tmp
[2022-09-27 17:14:19,282] {subprocess.py:74} INFO - Running command: ['bash', '-c', "echo 'accurate"]
[2022-09-27 17:14:19,298] {subprocess.py:85} INFO - Output:
[2022-09-27 17:14:19,304] {subprocess.py:89} INFO - bash: -c: line 0: unexpected EOF while looking for matching `''
[2022-09-27 17:14:19,305] {subprocess.py:89} INFO - bash: -c: line 1: syntax error: unexpected end of file
[2022-09-27 17:14:19,306] {subprocess.py:93} INFO - Command exited with return code 1
[2022-09-27 17:14:19,327] {taskinstance.py:1700} ERROR - Task failed with exception
Traceback (most recent call last):
  File "/home/airflow/.local/lib/python3.7/site-packages/airflow/models/taskinstance.py", line 1329, in _run_raw_task
    self._execute_task_with_callbacks(context)
  File "/home/airflow/.local/lib/python3.7/site-packages/airflow/models/taskinstance.py", line 1455, in _execute_task_with_callbacks
    result = self._execute_task(context, self.task)
  File "/home/airflow/.local/lib/python3.7/site-packages/airflow/models/taskinstance.py", line 1511, in _execute_task
    result = execute_callable(context=context)
  File "/home/airflow/.local/lib/python3.7/site-packages/airflow/operators/bash.py", line 188, in execute
    f'Bash command failed. The command returned a non-zero exit code {result.exit_code}.'
airflow.exceptions.AirflowException: Bash command failed. The command returned a non-zero exit code 1.
[2022-09-27 17:14:19,344] {taskinstance.py:1277} INFO - Marking task as FAILED. dag_id=first_dag, task_id=accurate, execution_date=20220926T000000, start_date=20220927T171418, end_date=20220927T171419
[2022-09-27 17:14:19,367] {standard_task_runner.py:92} ERROR - Failed to execute job 145 for task accurate
Traceback (most recent call last):
  File "/home/airflow/.local/lib/python3.7/site-packages/airflow/task/task_runner/standard_task_runner.py", line 85, in _start_by_fork
    args.func(args, dag=self.dag)
  File "/home/airflow/.local/lib/python3.7/site-packages/airflow/cli/cli_parser.py", line 48, in command
    return func(*args, **kwargs)
  File "/home/airflow/.local/lib/python3.7/site-packages/airflow/utils/cli.py", line 92, in wrapper
    return f(*args, **kwargs)
  File "/home/airflow/.local/lib/python3.7/site-packages/airflow/cli/commands/task_command.py", line 298, in task_run
    _run_task_by_selected_method(args, dag, ti)
  File "/home/airflow/.local/lib/python3.7/site-packages/airflow/cli/commands/task_command.py", line 107, in _run_task_by_selected_method
    _run_raw_task(args, ti)
  File "/home/airflow/.local/lib/python3.7/site-packages/airflow/cli/commands/task_command.py", line 184, in _run_raw_task
    error_file=args.error_file,
  File "/home/airflow/.local/lib/python3.7/site-packages/airflow/utils/session.py", line 70, in wrapper
    return func(*args, session=session, **kwargs)
  File "/home/airflow/.local/lib/python3.7/site-packages/airflow/models/taskinstance.py", line 1329, in _run_raw_task
    self._execute_task_with_callbacks(context)
  File "/home/airflow/.local/lib/python3.7/site-packages/airflow/models/taskinstance.py", line 1455, in _execute_task_with_callbacks
    result = self._execute_task(context, self.task)
  File "/home/airflow/.local/lib/python3.7/site-packages/airflow/models/taskinstance.py", line 1511, in _execute_task
    result = execute_callable(context=context)
  File "/home/airflow/.local/lib/python3.7/site-packages/airflow/operators/bash.py", line 188, in execute
    f'Bash command failed. The command returned a non-zero exit code {result.exit_code}.'
airflow.exceptions.AirflowException: Bash command failed. The command returned a non-zero exit code 1.
[2022-09-27 17:14:19,409] {local_task_job.py:154} INFO - Task exited with return code 1
[2022-09-27 17:14:19,442] {local_task_job.py:264} INFO - 0 downstream tasks scheduled from follow-on schedule check
