[2022-09-28 06:03:46,104] {taskinstance.py:1032} INFO - Dependencies all met for <TaskInstance: upload_to_gcs.upload manual__2022-09-28T06:03:41.683818+00:00 [queued]>
[2022-09-28 06:03:46,125] {taskinstance.py:1032} INFO - Dependencies all met for <TaskInstance: upload_to_gcs.upload manual__2022-09-28T06:03:41.683818+00:00 [queued]>
[2022-09-28 06:03:46,125] {taskinstance.py:1238} INFO - 
--------------------------------------------------------------------------------
[2022-09-28 06:03:46,126] {taskinstance.py:1239} INFO - Starting attempt 1 of 2
[2022-09-28 06:03:46,127] {taskinstance.py:1240} INFO - 
--------------------------------------------------------------------------------
[2022-09-28 06:03:46,150] {taskinstance.py:1259} INFO - Executing <Task(PythonOperator): upload> on 2022-09-28 06:03:41.683818+00:00
[2022-09-28 06:03:46,156] {standard_task_runner.py:52} INFO - Started process 221 to run task
[2022-09-28 06:03:46,160] {standard_task_runner.py:76} INFO - Running: ['***', 'tasks', 'run', 'upload_to_gcs', 'upload', 'manual__2022-09-28T06:03:41.683818+00:00', '--job-id', '236', '--raw', '--subdir', 'DAGS_FOLDER/upload_dag.py', '--cfg-path', '/tmp/tmpmf1scnr0', '--error-file', '/tmp/tmp92sz7lbm']
[2022-09-28 06:03:46,162] {standard_task_runner.py:77} INFO - Job 236: Subtask upload
[2022-09-28 06:03:46,243] {logging_mixin.py:109} INFO - Running <TaskInstance: upload_to_gcs.upload manual__2022-09-28T06:03:41.683818+00:00 [running]> on host 84f9143336ff
[2022-09-28 06:03:46,351] {taskinstance.py:1426} INFO - Exporting the following env vars:
AIRFLOW_CTX_DAG_OWNER=***
AIRFLOW_CTX_DAG_ID=upload_to_gcs
AIRFLOW_CTX_TASK_ID=upload
AIRFLOW_CTX_EXECUTION_DATE=2022-09-28T06:03:41.683818+00:00
AIRFLOW_CTX_DAG_RUN_ID=manual__2022-09-28T06:03:41.683818+00:00
[2022-09-28 06:03:46,387] {taskinstance.py:1700} ERROR - Task failed with exception
Traceback (most recent call last):
  File "/home/airflow/.local/lib/python3.7/site-packages/airflow/models/taskinstance.py", line 1329, in _run_raw_task
    self._execute_task_with_callbacks(context)
  File "/home/airflow/.local/lib/python3.7/site-packages/airflow/models/taskinstance.py", line 1455, in _execute_task_with_callbacks
    result = self._execute_task(context, self.task)
  File "/home/airflow/.local/lib/python3.7/site-packages/airflow/models/taskinstance.py", line 1511, in _execute_task
    result = execute_callable(context=context)
  File "/home/airflow/.local/lib/python3.7/site-packages/airflow/operators/python.py", line 174, in execute
    return_value = self.execute_callable()
  File "/home/airflow/.local/lib/python3.7/site-packages/airflow/operators/python.py", line 185, in execute_callable
    return self.python_callable(*self.op_args, **self.op_kwargs)
  File "/opt/airflow/dags/upload_dag.py", line 38, in upload_blob
    blob.upload_from_filename(source_file_name)
  File "/home/airflow/.local/lib/python3.7/site-packages/google/cloud/storage/blob.py", line 2720, in upload_from_filename
    with open(filename, "rb") as file_obj:
FileNotFoundError: [Errno 2] No such file or directory: 'C:/Users/Febian/Documents/Google_cloud/Proyek/File/countries.csv'
[2022-09-28 06:03:46,441] {taskinstance.py:1277} INFO - Marking task as UP_FOR_RETRY. dag_id=upload_to_gcs, task_id=upload, execution_date=20220928T060341, start_date=20220928T060346, end_date=20220928T060346
[2022-09-28 06:03:46,511] {standard_task_runner.py:92} ERROR - Failed to execute job 236 for task upload
Traceback (most recent call last):
  File "/home/airflow/.local/lib/python3.7/site-packages/airflow/task/task_runner/standard_task_runner.py", line 85, in _start_by_fork
    args.func(args, dag=self.dag)
  File "/home/airflow/.local/lib/python3.7/site-packages/airflow/cli/cli_parser.py", line 48, in command
    return func(*args, **kwargs)
  File "/home/airflow/.local/lib/python3.7/site-packages/airflow/utils/cli.py", line 92, in wrapper
    return f(*args, **kwargs)
  File "/home/airflow/.local/lib/python3.7/site-packages/airflow/cli/commands/task_command.py", line 298, in task_run
    _run_task_by_selected_method(args, dag, ti)
  File "/home/airflow/.local/lib/python3.7/site-packages/airflow/cli/commands/task_command.py", line 107, in _run_task_by_selected_method
    _run_raw_task(args, ti)
  File "/home/airflow/.local/lib/python3.7/site-packages/airflow/cli/commands/task_command.py", line 184, in _run_raw_task
    error_file=args.error_file,
  File "/home/airflow/.local/lib/python3.7/site-packages/airflow/utils/session.py", line 70, in wrapper
    return func(*args, session=session, **kwargs)
  File "/home/airflow/.local/lib/python3.7/site-packages/airflow/models/taskinstance.py", line 1329, in _run_raw_task
    self._execute_task_with_callbacks(context)
  File "/home/airflow/.local/lib/python3.7/site-packages/airflow/models/taskinstance.py", line 1455, in _execute_task_with_callbacks
    result = self._execute_task(context, self.task)
  File "/home/airflow/.local/lib/python3.7/site-packages/airflow/models/taskinstance.py", line 1511, in _execute_task
    result = execute_callable(context=context)
  File "/home/airflow/.local/lib/python3.7/site-packages/airflow/operators/python.py", line 174, in execute
    return_value = self.execute_callable()
  File "/home/airflow/.local/lib/python3.7/site-packages/airflow/operators/python.py", line 185, in execute_callable
    return self.python_callable(*self.op_args, **self.op_kwargs)
  File "/opt/airflow/dags/upload_dag.py", line 38, in upload_blob
    blob.upload_from_filename(source_file_name)
  File "/home/airflow/.local/lib/python3.7/site-packages/google/cloud/storage/blob.py", line 2720, in upload_from_filename
    with open(filename, "rb") as file_obj:
FileNotFoundError: [Errno 2] No such file or directory: 'C:/Users/Febian/Documents/Google_cloud/Proyek/File/countries.csv'
[2022-09-28 06:03:46,535] {local_task_job.py:154} INFO - Task exited with return code 1
[2022-09-28 06:03:46,621] {local_task_job.py:264} INFO - 0 downstream tasks scheduled from follow-on schedule check
