[2022-09-28 05:33:16,714] {taskinstance.py:1032} INFO - Dependencies all met for <TaskInstance: upload_to_gcs.upload scheduled__2022-09-27T00:00:00+00:00 [queued]>
[2022-09-28 05:33:16,741] {taskinstance.py:1032} INFO - Dependencies all met for <TaskInstance: upload_to_gcs.upload scheduled__2022-09-27T00:00:00+00:00 [queued]>
[2022-09-28 05:33:16,742] {taskinstance.py:1238} INFO - 
--------------------------------------------------------------------------------
[2022-09-28 05:33:16,743] {taskinstance.py:1239} INFO - Starting attempt 2 of 2
[2022-09-28 05:33:16,744] {taskinstance.py:1240} INFO - 
--------------------------------------------------------------------------------
[2022-09-28 05:33:16,791] {taskinstance.py:1259} INFO - Executing <Task(PythonOperator): upload> on 2022-09-27 00:00:00+00:00
[2022-09-28 05:33:16,810] {standard_task_runner.py:52} INFO - Started process 377 to run task
[2022-09-28 05:33:16,814] {standard_task_runner.py:76} INFO - Running: ['***', 'tasks', 'run', 'upload_to_gcs', 'upload', 'scheduled__2022-09-27T00:00:00+00:00', '--job-id', '221', '--raw', '--subdir', 'DAGS_FOLDER/upload_dag.py', '--cfg-path', '/tmp/tmpxgjgq6ph', '--error-file', '/tmp/tmpyramg2tk']
[2022-09-28 05:33:16,815] {standard_task_runner.py:77} INFO - Job 221: Subtask upload
[2022-09-28 05:33:16,905] {logging_mixin.py:109} INFO - Running <TaskInstance: upload_to_gcs.upload scheduled__2022-09-27T00:00:00+00:00 [running]> on host 7339e28b3b1f
[2022-09-28 05:33:17,029] {taskinstance.py:1426} INFO - Exporting the following env vars:
AIRFLOW_CTX_DAG_OWNER=***
AIRFLOW_CTX_DAG_ID=upload_to_gcs
AIRFLOW_CTX_TASK_ID=upload
AIRFLOW_CTX_EXECUTION_DATE=2022-09-27T00:00:00+00:00
AIRFLOW_CTX_DAG_RUN_ID=scheduled__2022-09-27T00:00:00+00:00
[2022-09-28 05:33:17,033] {taskinstance.py:1700} ERROR - Task failed with exception
Traceback (most recent call last):
  File "/home/airflow/.local/lib/python3.7/site-packages/airflow/models/taskinstance.py", line 1329, in _run_raw_task
    self._execute_task_with_callbacks(context)
  File "/home/airflow/.local/lib/python3.7/site-packages/airflow/models/taskinstance.py", line 1455, in _execute_task_with_callbacks
    result = self._execute_task(context, self.task)
  File "/home/airflow/.local/lib/python3.7/site-packages/airflow/models/taskinstance.py", line 1511, in _execute_task
    result = execute_callable(context=context)
  File "/home/airflow/.local/lib/python3.7/site-packages/airflow/operators/python.py", line 174, in execute
    return_value = self.execute_callable()
  File "/home/airflow/.local/lib/python3.7/site-packages/airflow/operators/python.py", line 185, in execute_callable
    return self.python_callable(*self.op_args, **self.op_kwargs)
  File "/opt/airflow/dags/upload_dag.py", line 54, in upload_to_gcs
    client = storage.Client()
  File "/home/airflow/.local/lib/python3.7/site-packages/google/cloud/storage/client.py", line 128, in __init__
    _http=_http,
  File "/home/airflow/.local/lib/python3.7/site-packages/google/cloud/client.py", line 318, in __init__
    _ClientProjectMixin.__init__(self, project=project, credentials=credentials)
  File "/home/airflow/.local/lib/python3.7/site-packages/google/cloud/client.py", line 266, in __init__
    project = self._determine_default(project)
  File "/home/airflow/.local/lib/python3.7/site-packages/google/cloud/client.py", line 285, in _determine_default
    return _determine_default_project(project)
  File "/home/airflow/.local/lib/python3.7/site-packages/google/cloud/_helpers.py", line 186, in _determine_default_project
    _, project = google.auth.default()
  File "/home/airflow/.local/lib/python3.7/site-packages/google/auth/_default.py", line 459, in default
    credentials, project_id = checker()
  File "/home/airflow/.local/lib/python3.7/site-packages/google/auth/_default.py", line 222, in _get_explicit_environ_credentials
    os.environ[environment_vars.CREDENTIALS]
  File "/home/airflow/.local/lib/python3.7/site-packages/google/auth/_default.py", line 108, in load_credentials_from_file
    "File {} was not found.".format(filename)
google.auth.exceptions.DefaultCredentialsError: File google_credentials.json was not found.
[2022-09-28 05:33:17,072] {taskinstance.py:1277} INFO - Marking task as FAILED. dag_id=upload_to_gcs, task_id=upload, execution_date=20220927T000000, start_date=20220928T053316, end_date=20220928T053317
[2022-09-28 05:33:17,099] {standard_task_runner.py:92} ERROR - Failed to execute job 221 for task upload
Traceback (most recent call last):
  File "/home/airflow/.local/lib/python3.7/site-packages/airflow/task/task_runner/standard_task_runner.py", line 85, in _start_by_fork
    args.func(args, dag=self.dag)
  File "/home/airflow/.local/lib/python3.7/site-packages/airflow/cli/cli_parser.py", line 48, in command
    return func(*args, **kwargs)
  File "/home/airflow/.local/lib/python3.7/site-packages/airflow/utils/cli.py", line 92, in wrapper
    return f(*args, **kwargs)
  File "/home/airflow/.local/lib/python3.7/site-packages/airflow/cli/commands/task_command.py", line 298, in task_run
    _run_task_by_selected_method(args, dag, ti)
  File "/home/airflow/.local/lib/python3.7/site-packages/airflow/cli/commands/task_command.py", line 107, in _run_task_by_selected_method
    _run_raw_task(args, ti)
  File "/home/airflow/.local/lib/python3.7/site-packages/airflow/cli/commands/task_command.py", line 184, in _run_raw_task
    error_file=args.error_file,
  File "/home/airflow/.local/lib/python3.7/site-packages/airflow/utils/session.py", line 70, in wrapper
    return func(*args, session=session, **kwargs)
  File "/home/airflow/.local/lib/python3.7/site-packages/airflow/models/taskinstance.py", line 1329, in _run_raw_task
    self._execute_task_with_callbacks(context)
  File "/home/airflow/.local/lib/python3.7/site-packages/airflow/models/taskinstance.py", line 1455, in _execute_task_with_callbacks
    result = self._execute_task(context, self.task)
  File "/home/airflow/.local/lib/python3.7/site-packages/airflow/models/taskinstance.py", line 1511, in _execute_task
    result = execute_callable(context=context)
  File "/home/airflow/.local/lib/python3.7/site-packages/airflow/operators/python.py", line 174, in execute
    return_value = self.execute_callable()
  File "/home/airflow/.local/lib/python3.7/site-packages/airflow/operators/python.py", line 185, in execute_callable
    return self.python_callable(*self.op_args, **self.op_kwargs)
  File "/opt/airflow/dags/upload_dag.py", line 54, in upload_to_gcs
    client = storage.Client()
  File "/home/airflow/.local/lib/python3.7/site-packages/google/cloud/storage/client.py", line 128, in __init__
    _http=_http,
  File "/home/airflow/.local/lib/python3.7/site-packages/google/cloud/client.py", line 318, in __init__
    _ClientProjectMixin.__init__(self, project=project, credentials=credentials)
  File "/home/airflow/.local/lib/python3.7/site-packages/google/cloud/client.py", line 266, in __init__
    project = self._determine_default(project)
  File "/home/airflow/.local/lib/python3.7/site-packages/google/cloud/client.py", line 285, in _determine_default
    return _determine_default_project(project)
  File "/home/airflow/.local/lib/python3.7/site-packages/google/cloud/_helpers.py", line 186, in _determine_default_project
    _, project = google.auth.default()
  File "/home/airflow/.local/lib/python3.7/site-packages/google/auth/_default.py", line 459, in default
    credentials, project_id = checker()
  File "/home/airflow/.local/lib/python3.7/site-packages/google/auth/_default.py", line 222, in _get_explicit_environ_credentials
    os.environ[environment_vars.CREDENTIALS]
  File "/home/airflow/.local/lib/python3.7/site-packages/google/auth/_default.py", line 108, in load_credentials_from_file
    "File {} was not found.".format(filename)
google.auth.exceptions.DefaultCredentialsError: File google_credentials.json was not found.
[2022-09-28 05:33:17,153] {local_task_job.py:154} INFO - Task exited with return code 1
[2022-09-28 05:33:17,199] {local_task_job.py:264} INFO - 0 downstream tasks scheduled from follow-on schedule check
